<sdf version='1.6'>
  <model name='panda'>
    <link name='panda_link0'>
      <pose frame=''>0 0 0 0 -0 0</pose>
      <inertial>
        <pose frame=''>0 0 0 0 -0 0</pose>
        <mass>3.06</mass>
        <inertia>
          <ixx>0.3</ixx>
          <ixy>0</ixy>
          <ixz>0</ixz>
          <iyy>0.3</iyy>
          <iyz>0</iyz>
          <izz>0.3</izz>
        </inertia>
      </inertial>
      <collision name='panda_link0_collision'>
        <pose frame=''>0 0 0 0 -0 0</pose>
        <geometry>
          <mesh>
            <scale>1 1 1</scale>
            <uri>model://franka_description/meshes/collision/link0.stl</uri>
          </mesh>
        </geometry>
        <surface>
          <contact>
            <ode/>
          </contact>
          <friction>
            <ode>
              <mu>0.2</mu>
              <mu2>0.2</mu2>
            </ode>
          </friction>
        </surface>
      </collision>
      <visual name='panda_link0_visual'>
        <pose frame=''>0 0 0 0 -0 0</pose>
        <geometry>
          <mesh>
            <scale>1 1 1</scale>
            <uri>model://franka_description/meshes/visual/link0.dae</uri>
          </mesh>
        </geometry>
        <material>
          <script>
            <name>Gazebo/Grey</name>
            <uri>file://media/materials/scripts/gazebo.material</uri>
          </script>
        </material>
      </visual>
      <gravity>1</gravity>
      <velocity_decay/>
    </link>
    <joint name='robot_to_world' type='fixed'>
      <child>panda_link0</child>
      <parent>world</parent>
    </joint>
    <link name='panda_link1'>
      <pose frame=''>0 0 0.333 0 -0 0</pose>
      <inertial>
        <pose frame=''>0 0 0 0 -0 0</pose>
        <mass>2.34</mass>
        <inertia>
          <ixx>0.3</ixx>
          <ixy>0</ixy>
          <ixz>0</ixz>
          <iyy>0.3</iyy>
          <iyz>0</iyz>
          <izz>0.3</izz>
        </inertia>
      </inertial>
      <collision name='panda_link1_collision'>
        <pose frame=''>0 0 0 0 -0 0</pose>
        <geometry>
          <mesh>
            <scale>1 1 1</scale>
            <uri>model://franka_description/meshes/collision/link1.stl</uri>
          </mesh>
        </geometry>
        <surface>
          <contact>
            <ode/>
          </contact>
          <friction>
            <ode>
              <mu>0.2</mu>
              <mu2>0.2</mu2>
            </ode>
          </friction>
        </surface>
      </collision>
      <visual name='panda_link1_visual'>
        <pose frame=''>0 0 0 0 -0 0</pose>
        <geometry>
          <mesh>
            <scale>1 1 1</scale>
            <uri>model://franka_description/meshes/visual/link1.dae</uri>
          </mesh>
        </geometry>
        <material>
          <script>
            <name>Gazebo/White</name>
            <uri>file://media/materials/scripts/gazebo.material</uri>
          </script>
        </material>
      </visual>
      <velocity_decay/>
      <sensor name='panda_link1_bumper' type='contact'>
        <topic>/bump_topic/panda_link1</topic>
        <plugin name='gazebo_ros_bumper_controller_panda_link1' filename='libgazebo_ros_bumper.so'>
          <topic>/bump_topic/panda_link1</topic>
          <alwaysOn>1</alwaysOn>
          <updateRate>100.0</updateRate>
          <bumperTopicName>/panda/bumper/panda_link1</bumperTopicName>
        </plugin>
        <contact>
          <collision>panda_link1_collision</collision>
          <topic>/bump_topic/panda_link1</topic>
        </contact>
      </sensor>
      <gravity>1</gravity>
      <velocity_decay/>
    </link>
    <joint name='panda_joint1' type='revolute'>
      <child>panda_link1</child>
      <parent>panda_link0</parent>
      <axis>
        <xyz>0 0 1</xyz>
        <limit>
          <lower>-2.8973</lower>
          <upper>2.8973</upper>
          <effort>87</effort>
          <velocity>2.175</velocity>
        </limit>
        <dynamics>
          <damping>1</damping>
          <friction>0</friction>
          <spring_reference>0</spring_reference>
          <spring_stiffness>0</spring_stiffness>
        </dynamics>
        <use_parent_model_frame>1</use_parent_model_frame>
      </axis>
    </joint>
    <link name='panda_link2'>
      <pose frame=''>0 0 0.333 -1.5708 0 0</pose>
      <inertial>
        <pose frame=''>0 0 0 0 -0 0</pose>
        <mass>2.36</mass>
        <inertia>
          <ixx>0.3</ixx>
          <ixy>0</ixy>
          <ixz>0</ixz>
          <iyy>0.3</iyy>
          <iyz>0</iyz>
          <izz>0.3</izz>
        </inertia>
      </inertial>
      <collision name='panda_link2_collision'>
        <pose frame=''>0 0 0 0 -0 0</pose>
        <geometry>
          <mesh>
            <scale>1 1 1</scale>
            <uri>model://franka_description/meshes/collision/link2.stl</uri>
          </mesh>
        </geometry>
        <surface>
          <contact>
            <ode/>
          </contact>
          <friction>
            <ode>
              <mu>0.2</mu>
              <mu2>0.2</mu2>
            </ode>
          </friction>
        </surface>
      </collision>
      <visual name='panda_link2_visual'>
        <pose frame=''>0 0 0 0 -0 0</pose>
        <geometry>
          <mesh>
            <scale>1 1 1</scale>
            <uri>model://franka_description/meshes/visual/link2.dae</uri>
          </mesh>
        </geometry>
        <material>
          <script>
            <name>Gazebo/White</name>
            <uri>file://media/materials/scripts/gazebo.material</uri>
          </script>
        </material>
      </visual>
      <velocity_decay/>
      <sensor name='panda_link2_bumper' type='contact'>
        <topic>/bump_topic/panda_link2</topic>
        <plugin name='gazebo_ros_bumper_controller_panda_link2' filename='libgazebo_ros_bumper.so'>
          <topic>/bump_topic/panda_link2</topic>
          <alwaysOn>1</alwaysOn>
          <updateRate>100.0</updateRate>
          <bumperTopicName>/panda/bumper/panda_link2</bumperTopicName>
        </plugin>
        <contact>
          <collision>panda_link2_collision</collision>
          <topic>/bump_topic/panda_link2</topic>
        </contact>
      </sensor>
      <gravity>1</gravity>
      <velocity_decay/>
    </link>
    <joint name='panda_joint2' type='revolute'>
      <child>panda_link2</child>
      <parent>panda_link1</parent>
      <axis>
        <xyz>0 1 0</xyz>
        <limit>
          <lower>-1.7628</lower>
          <upper>1.7628</upper>
          <effort>87</effort>
          <velocity>2.175</velocity>
        </limit>
        <dynamics>
          <damping>1</damping>
          <friction>0</friction>
          <spring_reference>0</spring_reference>
          <spring_stiffness>0</spring_stiffness>
        </dynamics>
        <use_parent_model_frame>1</use_parent_model_frame>
      </axis>
    </joint>
    <link name='panda_link3'>
      <pose frame=''>0 -0 0.649 0 -0 0</pose>
      <inertial>
        <pose frame=''>0 0 0 0 -0 0</pose>
        <mass>2.38</mass>
        <inertia>
          <ixx>0.3</ixx>
          <ixy>0</ixy>
          <ixz>0</ixz>
          <iyy>0.3</iyy>
          <iyz>0</iyz>
          <izz>0.3</izz>
        </inertia>
      </inertial>
      <collision name='panda_link3_collision'>
        <pose frame=''>0 0 0 0 -0 0</pose>
        <geometry>
          <mesh>
            <scale>1 1 1</scale>
            <uri>model://franka_description/meshes/collision/link3.stl</uri>
          </mesh>
        </geometry>
        <surface>
          <contact>
            <ode/>
          </contact>
          <friction>
            <ode>
              <mu>0.2</mu>
              <mu2>0.2</mu2>
            </ode>
          </friction>
        </surface>
      </collision>
      <visual name='panda_link3_visual'>
        <pose frame=''>0 0 0 0 -0 0</pose>
        <geometry>
          <mesh>
            <scale>1 1 1</scale>
            <uri>model://franka_description/meshes/visual/link3.dae</uri>
          </mesh>
        </geometry>
        <material>
          <script>
            <name>Gazebo/White</name>
            <uri>file://media/materials/scripts/gazebo.material</uri>
          </script>
        </material>
      </visual>
      <velocity_decay/>
      <sensor name='panda_link3_bumper' type='contact'>
        <topic>/bump_topic/panda_link3</topic>
        <plugin name='gazebo_ros_bumper_controller_panda_link3' filename='libgazebo_ros_bumper.so'>
          <topic>/bump_topic/panda_link3</topic>
          <alwaysOn>1</alwaysOn>
          <updateRate>100.0</updateRate>
          <bumperTopicName>/panda/bumper/panda_link3</bumperTopicName>
        </plugin>
        <contact>
          <collision>panda_link3_collision</collision>
          <topic>/bump_topic/panda_link3</topic>
        </contact>
      </sensor>
      <gravity>1</gravity>
      <velocity_decay/>
    </link>
    <joint name='panda_joint3' type='revolute'>
      <child>panda_link3</child>
      <parent>panda_link2</parent>
      <axis>
        <xyz>0 0 1</xyz>
        <limit>
          <lower>-2.8973</lower>
          <upper>2.8973</upper>
          <effort>87</effort>
          <velocity>2.175</velocity>
        </limit>
        <dynamics>
          <damping>1</damping>
          <friction>0</friction>
          <spring_reference>0</spring_reference>
          <spring_stiffness>0</spring_stiffness>
        </dynamics>
        <use_parent_model_frame>1</use_parent_model_frame>
      </axis>
    </joint>
    <link name='panda_link4'>
      <pose frame=''>0.0825 -0 0.649 1.5708 -0 0</pose>
      <inertial>
        <pose frame=''>0 0 0 0 -0 0</pose>
        <mass>2.43</mass>
        <inertia>
          <ixx>0.3</ixx>
          <ixy>0</ixy>
          <ixz>0</ixz>
          <iyy>0.3</iyy>
          <iyz>0</iyz>
          <izz>0.3</izz>
        </inertia>
      </inertial>
      <collision name='panda_link4_collision'>
        <pose frame=''>0 0 0 0 -0 0</pose>
        <geometry>
          <mesh>
            <scale>1 1 1</scale>
            <uri>model://franka_description/meshes/collision/link4.stl</uri>
          </mesh>
        </geometry>
        <surface>
          <contact>
            <ode/>
          </contact>
          <friction>
            <ode>
              <mu>0.2</mu>
              <mu2>0.2</mu2>
            </ode>
          </friction>
        </surface>
      </collision>
      <visual name='panda_link4_visual'>
        <pose frame=''>0 0 0 0 -0 0</pose>
        <geometry>
          <mesh>
            <scale>1 1 1</scale>
            <uri>model://franka_description/meshes/visual/link4.dae</uri>
          </mesh>
        </geometry>
        <material>
          <script>
            <name>Gazebo/White</name>
            <uri>file://media/materials/scripts/gazebo.material</uri>
          </script>
        </material>
      </visual>
      <velocity_decay/>
      <sensor name='panda_link4_bumper' type='contact'>
        <topic>/bump_topic/panda_link4</topic>
        <plugin name='gazebo_ros_bumper_controller_panda_link4' filename='libgazebo_ros_bumper.so'>
          <topic>/bump_topic/panda_link4</topic>
          <alwaysOn>1</alwaysOn>
          <updateRate>100.0</updateRate>
          <bumperTopicName>/panda/bumper/panda_link4</bumperTopicName>
        </plugin>
        <contact>
          <collision>panda_link4_collision</collision>
          <topic>/bump_topic/panda_link4</topic>
        </contact>
      </sensor>
      <gravity>1</gravity>
      <velocity_decay/>
    </link>
    <joint name='panda_joint4' type='revolute'>
      <child>panda_link4</child>
      <parent>panda_link3</parent>
      <axis>
        <xyz>0 -1 0</xyz>
        <limit>
          <lower>-3.0718</lower>
          <upper>-0.0698</upper>
          <effort>87</effort>
          <velocity>2.175</velocity>
        </limit>
        <dynamics>
          <damping>1</damping>
          <friction>0</friction>
          <spring_reference>0</spring_reference>
          <spring_stiffness>0</spring_stiffness>
        </dynamics>
        <use_parent_model_frame>1</use_parent_model_frame>
      </axis>
    </joint>
    <link name='panda_link5'>
      <pose frame=''>-0 0 1.033 0 -0 0</pose>
      <inertial>
        <pose frame=''>0 0 0 0 -0 0</pose>
        <mass>3.5</mass>
        <inertia>
          <ixx>0.3</ixx>
          <ixy>0</ixy>
          <ixz>0</ixz>
          <iyy>0.3</iyy>
          <iyz>0</iyz>
          <izz>0.3</izz>
        </inertia>
      </inertial>
      <collision name='panda_link5_collision'>
        <pose frame=''>0 0 0 0 -0 0</pose>
        <geometry>
          <mesh>
            <scale>1 1 1</scale>
            <uri>model://franka_description/meshes/collision/link5.stl</uri>
          </mesh>
        </geometry>
        <surface>
          <contact>
            <ode/>
          </contact>
          <friction>
            <ode>
              <mu>0.2</mu>
              <mu2>0.2</mu2>
            </ode>
          </friction>
        </surface>
      </collision>
      <visual name='panda_link5_visual'>
        <pose frame=''>0 0 0 0 -0 0</pose>
        <geometry>
          <mesh>
            <scale>1 1 1</scale>
            <uri>model://franka_description/meshes/visual/link5.dae</uri>
          </mesh>
        </geometry>
        <material>
          <script>
            <name>Gazebo/White</name>
            <uri>file://media/materials/scripts/gazebo.material</uri>
          </script>
        </material>
      </visual>
      <velocity_decay/>
      <sensor name='panda_link5_bumper' type='contact'>
        <topic>/bump_topic/panda_link5</topic>
        <plugin name='gazebo_ros_bumper_controller_panda_link5' filename='libgazebo_ros_bumper.so'>
          <topic>/bump_topic/panda_link5</topic>
          <alwaysOn>1</alwaysOn>
          <updateRate>100.0</updateRate>
          <bumperTopicName>/panda/bumper/panda_link5</bumperTopicName>
        </plugin>
        <contact>
          <collision>panda_link5_collision</collision>
          <topic>/bump_topic/panda_link5</topic>
        </contact>
      </sensor>
      <gravity>1</gravity>
      <velocity_decay/>
    </link>
    <joint name='panda_joint5' type='revolute'>
      <child>panda_link5</child>
      <parent>panda_link4</parent>
      <axis>
        <xyz>0 0 1</xyz>
        <limit>
          <lower>-2.8973</lower>
          <upper>2.8973</upper>
          <effort>12</effort>
          <velocity>2.61</velocity>
        </limit>
        <dynamics>
          <damping>1</damping>
          <friction>0</friction>
          <spring_reference>0</spring_reference>
          <spring_stiffness>0</spring_stiffness>
        </dynamics>
        <use_parent_model_frame>1</use_parent_model_frame>
      </axis>
    </joint>
    <link name='panda_link6'>
      <pose frame=''>-0 0 1.033 1.5708 -0 0</pose>
      <inertial>
        <pose frame=''>0 0 0 0 -0 0</pose>
        <mass>1.47</mass>
        <inertia>
          <ixx>0.3</ixx>
          <ixy>0</ixy>
          <ixz>0</ixz>
          <iyy>0.3</iyy>
          <iyz>0</iyz>
          <izz>0.3</izz>
        </inertia>
      </inertial>
      <collision name='panda_link6_collision'>
        <pose frame=''>0 0 0 0 -0 0</pose>
        <geometry>
          <mesh>
            <scale>1 1 1</scale>
            <uri>model://franka_description/meshes/collision/link6.stl</uri>
          </mesh>
        </geometry>
        <surface>
          <contact>
            <ode/>
          </contact>
          <friction>
            <ode>
              <mu>0.2</mu>
              <mu2>0.2</mu2>
            </ode>
          </friction>
        </surface>
      </collision>
      <visual name='panda_link6_visual'>
        <pose frame=''>0 0 0 0 -0 0</pose>
        <geometry>
          <mesh>
            <scale>1 1 1</scale>
            <uri>model://franka_description/meshes/visual/link6.dae</uri>
          </mesh>
        </geometry>
        <material>
          <script>
            <name>Gazebo/White</name>
            <uri>file://media/materials/scripts/gazebo.material</uri>
          </script>
        </material>
      </visual>
      <velocity_decay/>
      <sensor name='panda_link6_bumper' type='contact'>
        <topic>/bump_topic/panda_link6</topic>
        <plugin name='gazebo_ros_bumper_controller_panda_link6' filename='libgazebo_ros_bumper.so'>
          <topic>/bump_topic/panda_link6</topic>
          <alwaysOn>1</alwaysOn>
          <updateRate>100.0</updateRate>
          <bumperTopicName>/panda/bumper/panda_link6</bumperTopicName>
        </plugin>
        <contact>
          <collision>panda_link6_collision</collision>
          <topic>/bump_topic/panda_link6</topic>
        </contact>
      </sensor>
      <gravity>1</gravity>
      <velocity_decay/>
    </link>
    <joint name='panda_joint6' type='revolute'>
      <child>panda_link6</child>
      <parent>panda_link5</parent>
      <axis>
        <xyz>0 -1 0</xyz>
        <limit>
          <lower>-0.0175</lower>
          <upper>3.7525</upper>
          <effort>12</effort>
          <velocity>2.61</velocity>
        </limit>
        <dynamics>
          <damping>1</damping>
          <friction>0</friction>
          <spring_reference>0</spring_reference>
          <spring_stiffness>0</spring_stiffness>
        </dynamics>
        <use_parent_model_frame>1</use_parent_model_frame>
      </axis>
    </joint>
    <link name='panda_link7'>
      <pose frame=''>0.088 0 1.033 3.14159 -0 0</pose>
      <inertial>
        <pose frame=''>0.004295 -0.004295 0.07564 0 -0 0</pose>
        <mass>1.28625</mass>
        <inertia>
          <ixx>0.704514</ixx>
          <ixy>0.000171586</ixy>
          <ixz>-0.000449458</ixz>
          <iyy>0.704514</iyy>
          <iyz>0.000449458</iyz>
          <izz>0.700408</izz>
        </inertia>
      </inertial>
      <collision name='panda_link7_collision'>
        <pose frame=''>0 0 0 0 -0 0</pose>
        <geometry>
          <mesh>
            <scale>1 1 1</scale>
            <uri>model://franka_description/meshes/collision/link7.stl</uri>
          </mesh>
        </geometry>
        <surface>
          <contact>
            <ode/>
          </contact>
          <friction>
            <ode>
              <mu>0.2</mu>
              <mu2>0.2</mu2>
            </ode>
          </friction>
        </surface>
      </collision>
      <collision name='panda_link7_fixed_joint_lump__panda_hand_collision_1'>
        <pose frame=''>0 0 0.107 0 0 -0.785398</pose>
        <geometry>
          <mesh>
            <scale>1 1 1</scale>
            <uri>model://franka_description/meshes/collision/hand.stl</uri>
          </mesh>
        </geometry>
        <surface>
          <contact>
            <ode/>
          </contact>
          <friction>
            <ode>
              <mu>0.2</mu>
              <mu2>0.2</mu2>
            </ode>
          </friction>
        </surface>
      </collision>
      <collision name='panda_link7_fixed_joint_lump__panda_camera_collision_2'>
        <pose frame=''>0.035355 -0.035355 0.157 0 0 -0.785398</pose>
        <geometry>
          <box>
            <size>0.05 0.05 0.05</size>
          </box>
        </geometry>
      </collision>
      <visual name='panda_link7_visual'>
        <pose frame=''>0 0 0 0 -0 0</pose>
        <geometry>
          <mesh>
            <scale>1 1 1</scale>
            <uri>model://franka_description/meshes/visual/link7.dae</uri>
          </mesh>
        </geometry>
        <material>
          <script>
            <name>Gazebo/Grey</name>
            <uri>file://media/materials/scripts/gazebo.material</uri>
          </script>
        </material>
      </visual>
      <visual name='panda_link7_fixed_joint_lump__panda_hand_visual_1'>
        <pose frame=''>0 0 0.107 0 0 -0.785398</pose>
        <geometry>
          <mesh>
            <scale>1 1 1</scale>
            <uri>model://franka_description/meshes/visual/hand.dae</uri>
          </mesh>
        </geometry>
        <material>
          <script>
            <name>Gazebo/Grey</name>
            <uri>file://media/materials/scripts/gazebo.material</uri>
          </script>
        </material>
      </visual>
      <visual name='panda_link7_fixed_joint_lump__panda_camera_visual_2'>
        <pose frame=''>0.035355 -0.035355 0.157 0 0 -0.785398</pose>
        <geometry>
          <box>
            <size>0.05 0.05 0.05</size>
          </box>
        </geometry>
      </visual>
      <velocity_decay/>
      <sensor name='panda_link7_bumper' type='contact'>
        <topic>/bump_topic/panda_link7</topic>
        <plugin name='gazebo_ros_bumper_controller_panda_link7' filename='libgazebo_ros_bumper.so'>
          <topic>/bump_topic/panda_link7</topic>
          <alwaysOn>1</alwaysOn>
          <updateRate>100.0</updateRate>
          <bumperTopicName>/panda/bumper/panda_link7</bumperTopicName>
        </plugin>
        <contact>
          <collision>panda_link7_collision</collision>
          <collision>panda_link7_fixed_joint_lump__panda_hand_collision_1</collision>
          <topic>/bump_topic/panda_link7</topic>
        </contact>
      </sensor>
      <velocity_decay/>
      <velocity_decay/>
      <sensor name='panda_link8_bumper' type='contact'>
        <topic>/bump_topic/panda_link8</topic>
        <plugin name='gazebo_ros_bumper_controller_panda_link8' filename='libgazebo_ros_bumper.so'>
          <topic>/bump_topic/panda_link8</topic>
          <alwaysOn>1</alwaysOn>
          <updateRate>100.0</updateRate>
          <bumperTopicName>/panda/bumper/panda_link8</bumperTopicName>
        </plugin>
        <contact>
          <topic>/bump_topic/panda_link8</topic>
          <collision>panda_link7_collision_panda_link8</collision>
        </contact>
        <pose frame=''>0 0 0.107 0 -0 0</pose>
      </sensor>
      <velocity_decay/>
      <velocity_decay/>
      <sensor name='panda_hand_bumper' type='contact'>
        <topic>/bump_topic/panda_hand</topic>
        <plugin name='gazebo_ros_bumper_controller_panda_hand' filename='libgazebo_ros_bumper.so'>
          <topic>/bump_topic/panda_hand</topic>
          <alwaysOn>1</alwaysOn>
          <updateRate>100.0</updateRate>
          <bumperTopicName>/panda/bumper/panda_hand</bumperTopicName>
        </plugin>
        <contact>
          <topic>/bump_topic/panda_hand</topic>
          <collision>panda_link8_collision_panda_hand</collision>
        </contact>
        <pose frame=''>0 0 0.107 0 0 -0.785398</pose>
      </sensor>
      <gravity>1</gravity>
      <velocity_decay/>
    </link>
    <joint name='panda_joint7' type='revolute'>
      <child>panda_link7</child>
      <parent>panda_link6</parent>
      <axis>
        <xyz>0 -0 -1</xyz>
        <limit>
          <lower>-2.8973</lower>
          <upper>2.8973</upper>
          <effort>12</effort>
          <velocity>2.61</velocity>
        </limit>
        <dynamics>
          <damping>1</damping>
          <friction>0</friction>
          <spring_reference>0</spring_reference>
          <spring_stiffness>0</spring_stiffness>
        </dynamics>
        <use_parent_model_frame>1</use_parent_model_frame>
      </axis>
    </joint>
    <link name='panda_leftfinger'>
      <pose frame=''>0.088 -0 0.8676 3.14159 0 0.785398</pose>
      <inertial>
        <pose frame=''>0 0 0 0 -0 0</pose>
        <mass>0.01</mass>
        <inertia>
          <ixx>0.1</ixx>
          <ixy>0</ixy>
          <ixz>0</ixz>
          <iyy>0.1</iyy>
          <iyz>0</iyz>
          <izz>0.1</izz>
        </inertia>
      </inertial>
      <collision name='panda_leftfinger_collision'>
        <pose frame=''>0 0 0 0 -0 0</pose>
        <geometry>
          <mesh>
            <scale>1 1 1</scale>
            <uri>model://franka_description/meshes/collision/finger.stl</uri>
          </mesh>
        </geometry>
        <surface>
          <contact>
            <ode/>
          </contact>
          <friction>
            <ode>
              <mu>0.2</mu>
              <mu2>0.2</mu2>
            </ode>
          </friction>
        </surface>
      </collision>
      <visual name='panda_leftfinger_visual'>
        <pose frame=''>0 0 0 0 -0 0</pose>
        <geometry>
          <mesh>
            <scale>1 1 1</scale>
            <uri>model://franka_description/meshes/visual/finger.dae</uri>
          </mesh>
        </geometry>
        <material>
          <script>
            <name>Gazebo/Grey</name>
            <uri>file://media/materials/scripts/gazebo.material</uri>
          </script>
        </material>
      </visual>
      <velocity_decay/>
      <sensor name='panda_leftfinger_bumper' type='contact'>
        <topic>/bump_topic/panda_leftfinger</topic>
        <plugin name='gazebo_ros_bumper_controller_panda_leftfinger' filename='libgazebo_ros_bumper.so'>
          <topic>/bump_topic/panda_leftfinger</topic>
          <alwaysOn>1</alwaysOn>
          <updateRate>100.0</updateRate>
          <bumperTopicName>/panda/bumper/panda_leftfinger</bumperTopicName>
        </plugin>
        <contact>
          <collision>panda_leftfinger_collision</collision>
          <topic>/bump_topic/panda_leftfinger</topic>
        </contact>
      </sensor>
      <gravity>1</gravity>
      <velocity_decay/>
    </link>
    <joint name='panda_finger_joint1' type='prismatic'>
      <child>panda_leftfinger</child>
      <parent>panda_link7</parent>
      <axis>
        <xyz>0.707107 -0.707107 0</xyz>
        <limit>
          <lower>0</lower>
          <upper>0.04</upper>
          <effort>20</effort>
          <velocity>0.2</velocity>
        </limit>
        <dynamics>
          <spring_reference>0</spring_reference>
          <spring_stiffness>0</spring_stiffness>
        </dynamics>
        <use_parent_model_frame>1</use_parent_model_frame>
      </axis>
    </joint>
    <link name='panda_rightfinger'>
      <pose frame=''>0.088 -0 0.8676 3.14159 0 0.785398</pose>
      <inertial>
        <pose frame=''>0 0 0 0 -0 0</pose>
        <mass>0.01</mass>
        <inertia>
          <ixx>0.1</ixx>
          <ixy>0</ixy>
          <ixz>0</ixz>
          <iyy>0.1</iyy>
          <iyz>0</iyz>
          <izz>0.1</izz>
        </inertia>
      </inertial>
      <collision name='panda_rightfinger_collision'>
        <pose frame=''>0 0 0 0 -0 -3.14159</pose>
        <geometry>
          <mesh>
            <scale>1 1 1</scale>
            <uri>model://franka_description/meshes/collision/finger.stl</uri>
          </mesh>
        </geometry>
        <surface>
          <contact>
            <ode/>
          </contact>
          <friction>
            <ode>
              <mu>0.2</mu>
              <mu2>0.2</mu2>
            </ode>
          </friction>
        </surface>
      </collision>
      <visual name='panda_rightfinger_visual'>
        <pose frame=''>0 0 0 0 -0 -3.14159</pose>
        <geometry>
          <mesh>
            <scale>1 1 1</scale>
            <uri>model://franka_description/meshes/visual/finger.dae</uri>
          </mesh>
        </geometry>
        <material>
          <script>
            <name>Gazebo/Grey</name>
            <uri>file://media/materials/scripts/gazebo.material</uri>
          </script>
        </material>
      </visual>
      <velocity_decay/>
      <sensor name='panda_rightfinger_bumper' type='contact'>
        <topic>/bump_topic/panda_rightfinger</topic>
        <plugin name='gazebo_ros_bumper_controller_panda_rightfinger' filename='libgazebo_ros_bumper.so'>
          <topic>/bump_topic/panda_rightfinger</topic>
          <alwaysOn>1</alwaysOn>
          <updateRate>100.0</updateRate>
          <bumperTopicName>/panda/bumper/panda_rightfinger</bumperTopicName>
        </plugin>
        <contact>
          <collision>panda_rightfinger_collision</collision>
          <topic>/bump_topic/panda_rightfinger</topic>
        </contact>
      </sensor>
      <gravity>1</gravity>
      <velocity_decay/>
    </link>
    <joint name='panda_finger_joint2' type='prismatic'>
      <child>panda_rightfinger</child>
      <parent>panda_link7</parent>
      <axis>
        <xyz>-0.707107 0.707107 -0</xyz>
        <limit>
          <lower>0</lower>
          <upper>0.04</upper>
          <effort>20</effort>
          <velocity>0.2</velocity>
        </limit>
        <dynamics>
          <spring_reference>0</spring_reference>
          <spring_stiffness>0</spring_stiffness>
        </dynamics>
        <use_parent_model_frame>1</use_parent_model_frame>
      </axis>
    </joint>
    <link name='panda_probe_cyl'>
      <pose frame=''>0.088 -0 0.806 3.14159 0 0.785398</pose>
      <inertial>
        <pose frame=''>0 0 0.032354 0 -0 0</pose>
        <mass>0.0730199</mass>
        <inertia>
          <ixx>0.000134795</ixx>
          <ixy>0</ixy>
          <ixz>0</ixz>
          <iyy>0.000134795</iyy>
          <iyz>0</iyz>
          <izz>1.41135e-05</izz>
        </inertia>
      </inertial>
      <collision name='panda_probe_cyl_collision'>
        <pose frame=''>0 0 0 0 -0 0</pose>
        <geometry>
          <cylinder>
            <length>0.1</length>
            <radius>0.01</radius>
          </cylinder>
        </geometry>
        <surface>
          <contact>
            <ode/>
          </contact>
          <friction>
            <ode/>
          </friction>
        </surface>
      </collision>
      <collision name='panda_probe_cyl_fixed_joint_lump__panda_probe_ball_collision_1'>
        <pose frame=''>0 0 0.07 0 -0 0</pose>
        <geometry>
          <sphere>
            <radius>0.03</radius>
          </sphere>
        </geometry>
        <surface>
          <contact>
            <ode/>
          </contact>
          <friction>
            <ode/>
          </friction>
        </surface>
      </collision>
      <visual name='panda_probe_cyl_visual'>
        <pose frame=''>0 0 0 0 -0 0</pose>
        <geometry>
          <cylinder>
            <length>0.1</length>
            <radius>0.01</radius>
          </cylinder>
        </geometry>
        <material>
          <script>
            <uri>__default__</uri>
            <name>__default__</name>
          </script>
        </material>
      </visual>
      <visual name='panda_probe_cyl_fixed_joint_lump__panda_probe_ball_visual_1'>
        <pose frame=''>0 0 0.07 0 -0 0</pose>
        <geometry>
          <sphere>
            <radius>0.03</radius>
          </sphere>
        </geometry>
        <material>
          <script>
            <uri>__default__</uri>
            <name>__default__</name>
          </script>
        </material>
      </visual>
      <velocity_decay/>
      <sensor name='panda_probe_cyl_bumper' type='contact'>
        <topic>/bump_topic/panda_probe_cyl</topic>
        <plugin name='gazebo_ros_bumper_controller_panda_probe_cyl' filename='libgazebo_ros_bumper.so'>
          <topic>/bump_topic/panda_probe_cyl</topic>
          <alwaysOn>1</alwaysOn>
          <updateRate>100.0</updateRate>
          <bumperTopicName>/panda/bumper/panda_probe_cyl</bumperTopicName>
        </plugin>
        <contact>
          <collision>panda_probe_cyl_collision</collision>
          <collision>panda_probe_cyl_collision</collision>
          <topic>/bump_topic/panda_probe_cyl</topic>
        </contact>
      </sensor>
      <gravity>1</gravity>
      <velocity_decay/>
      <sensor name='panda_probe_ball_bumper' type='contact'>
        <topic>/bump_topic/panda_probe_ball</topic>
        <plugin name='gazebo_ros_bumper_controller_panda_probe_ball' filename='libgazebo_ros_bumper.so'>
          <topic>/bump_topic/panda_probe_ball</topic>
          <alwaysOn>1</alwaysOn>
          <updateRate>100.0</updateRate>
          <bumperTopicName>/panda/bumper/panda_probe_ball</bumperTopicName>
        </plugin>
        <contact>
          <collision>panda_probe_cyl_fixed_joint_lump__panda_probe_ball_collision_1</collision>
          <topic>/bump_topic/panda_probe_ball</topic>
          <collision>panda_probe_cyl_collision_panda_probe_ball</collision>
        </contact>
        <pose frame=''>0 0 0.07 0 -0 0</pose>
      </sensor>
    </link>
    <joint name='panda_probe_cyl_joint' type='revolute'>
      <child>panda_probe_cyl</child>
      <parent>panda_link7</parent>
      <axis>
        <xyz>0.707107 -0.707107 0</xyz>
        <limit>
          <lower>0</lower>
          <upper>0</upper>
          <effort>20</effort>
          <velocity>0</velocity>
        </limit>
        <dynamics>
          <spring_reference>0</spring_reference>
          <spring_stiffness>0</spring_stiffness>
        </dynamics>
        <use_parent_model_frame>1</use_parent_model_frame>
      </axis>
      <physics>
        <provide_feedback>1</provide_feedback>
        <ode>
          <provide_feedback>1</provide_feedback>
          <limit>
            <cfm>0</cfm>
            <erp>0.2</erp>
          </limit>
        </ode>
      </physics>
    </joint>
    <plugin name='ft_sensor_tool' filename='libgazebo_ros_ft_sensor.so'>
      <updateRate>1000.0</updateRate>
      <topicName>panda/ft/tool</topicName>
      <jointName>panda_probe_cyl_joint</jointName>
    </plugin>
    <static>0</static>
    <plugin name='gazebo_ros_control' filename='libgazebo_ros_control.so'/>
  </model>
</sdf>
