<?xml version="1.0" encoding="utf-8"?>
<!-- =================================================================================== -->
<!-- |    This document was autogenerated by xacro from panda_arm_hand.urdf.xacro      | -->
<!-- |    EDITING THIS FILE BY HAND IS NOT RECOMMENDED                                 | -->
<!-- =================================================================================== -->
<robot name="panda" xmlns:xacro="http://www.ros.org/wiki/xacro">
  <!-- end for simulation -->
  <!-- for simulation -->
  <link name="world"/>
  <joint name="robot_to_world" type="fixed">
    <parent link="world"/>
    <child link="panda_link0"/>
    <origin rpy="0.0 0.0 0.0" xyz="0.0 0.0 0.0"/>
  </joint>
  <!-- end for simulation -->
  <link name="panda_link0">
    <visual>
      <geometry>
        <mesh filename="package://franka_description/meshes/visual/link0.dae"/>
      </geometry>
    </visual>
    <collision>
      <geometry>
        <mesh filename="package://franka_description/meshes/collision/link0.stl"/>
      </geometry>
    </collision>
    <!-- for simulation -->
    <inertial>
      <origin rpy="0 0 0" xyz="0 0 0"/>
      <mass value="3.06"/>
      <inertia ixx="0.3" ixy="0.0" ixz="0.0" iyy="0.3" iyz="0.0" izz="0.3"/>
    </inertial>
    <!-- end for simulation -->
  </link>
  <link name="panda_link1">
    <visual>
      <geometry>
        <mesh filename="package://franka_description/meshes/visual/link1.dae"/>
      </geometry>
    </visual>
    <collision>
      <geometry>
        <mesh filename="package://franka_description/meshes/collision/link1.stl"/>
      </geometry>
    </collision>
    <!-- for simulation -->
    <inertial>
      <origin rpy="0 0 0" xyz="0 0 0"/>
      <mass value="2.34"/>
      <inertia ixx="0.3" ixy="0.0" ixz="0.0" iyy="0.3" iyz="0.0" izz="0.3"/>
    </inertial>
    <!-- end for simulation -->
  </link>
  <joint name="panda_joint1" type="revolute">
    <safety_controller k_position="100.0" k_velocity="40.0" soft_lower_limit="-2.8973" soft_upper_limit="2.8973"/>
    <origin rpy="0 0 0" xyz="0 0 0.333"/>
    <parent link="panda_link0"/>
    <child link="panda_link1"/>
    <axis xyz="0 0 1"/>
    <limit effort="87" lower="-2.8973" upper="2.8973" velocity="2.1750"/>
    <!-- for simulation -->
    <dynamics damping="1.0"/>
    <!-- end for simulation -->
  </joint>
  <link name="panda_link2">
    <visual>
      <geometry>
        <mesh filename="package://franka_description/meshes/visual/link2.dae"/>
      </geometry>
    </visual>
    <collision>
      <geometry>
        <mesh filename="package://franka_description/meshes/collision/link2.stl"/>
      </geometry>
    </collision>
    <!-- for simulation -->
    <inertial>
      <origin rpy="0 0 0" xyz="0 0 0"/>
      <mass value="2.36"/>
      <inertia ixx="0.3" ixy="0.0" ixz="0.0" iyy="0.3" iyz="0.0" izz="0.3"/>
    </inertial>
    <!-- end for simulation -->
  </link>
  <joint name="panda_joint2" type="revolute">
    <safety_controller k_position="100.0" k_velocity="40.0" soft_lower_limit="-1.7628" soft_upper_limit="1.7628"/>
    <origin rpy="-1.57079632679 0 0" xyz="0 0 0"/>
    <parent link="panda_link1"/>
    <child link="panda_link2"/>
    <axis xyz="0 0 1"/>
    <limit effort="87" lower="-1.7628" upper="1.7628" velocity="2.1750"/>
    <!-- for simulation -->
    <dynamics damping="1.0"/>
    <!-- end for simulation -->
  </joint>
  <link name="panda_link3">
    <visual>
      <geometry>
        <mesh filename="package://franka_description/meshes/visual/link3.dae"/>
      </geometry>
    </visual>
    <collision>
      <geometry>
        <mesh filename="package://franka_description/meshes/collision/link3.stl"/>
      </geometry>
    </collision>
    <!-- for simulation -->
    <inertial>
      <origin rpy="0 0 0" xyz="0 0 0"/>
      <mass value="2.38"/>
      <inertia ixx="0.3" ixy="0.0" ixz="0.0" iyy="0.3" iyz="0.0" izz="0.3"/>
    </inertial>
    <!-- end for simulation -->
  </link>
  <joint name="panda_joint3" type="revolute">
    <safety_controller k_position="100.0" k_velocity="40.0" soft_lower_limit="-2.8973" soft_upper_limit="2.8973"/>
    <origin rpy="1.57079632679 0 0" xyz="0 -0.316 0"/>
    <parent link="panda_link2"/>
    <child link="panda_link3"/>
    <axis xyz="0 0 1"/>
    <limit effort="87" lower="-2.8973" upper="2.8973" velocity="2.1750"/>
    <!-- for simulation -->
    <dynamics damping="1.0"/>
    <!-- end for simulation -->
  </joint>
  <link name="panda_link4">
    <visual>
      <geometry>
        <mesh filename="package://franka_description/meshes/visual/link4.dae"/>
      </geometry>
    </visual>
    <collision>
      <geometry>
        <mesh filename="package://franka_description/meshes/collision/link4.stl"/>
      </geometry>
    </collision>
    <!-- for simulation -->
    <inertial>
      <origin rpy="0 0 0" xyz="0 0 0"/>
      <mass value="2.43"/>
      <inertia ixx="0.3" ixy="0.0" ixz="0.0" iyy="0.3" iyz="0.0" izz="0.3"/>
    </inertial>
    <!-- end for simulation -->
  </link>
  <joint name="panda_joint4" type="revolute">
    <safety_controller k_position="100.0" k_velocity="40.0" soft_lower_limit="-3.0718" soft_upper_limit="-0.0698"/>
    <origin rpy="1.57079632679 0 0" xyz="0.0825 0 0"/>
    <parent link="panda_link3"/>
    <child link="panda_link4"/>
    <axis xyz="0 0 1"/>
    <limit effort="87" lower="-3.0718" upper="-0.0698" velocity="2.1750"/>
    <!-- for simulation -->
    <dynamics damping="1.0"/>
    <!-- end for simulation -->
  </joint>
  <link name="panda_link5">
    <visual>
      <geometry>
        <mesh filename="package://franka_description/meshes/visual/link5.dae"/>
      </geometry>
    </visual>
    <collision>
      <geometry>
        <mesh filename="package://franka_description/meshes/collision/link5.stl"/>
      </geometry>
    </collision>
    <!-- for simulation -->
    <inertial>
      <origin rpy="0 0 0" xyz="0 0 0"/>
      <mass value="3.5"/>
      <inertia ixx="0.3" ixy="0.0" ixz="0.0" iyy="0.3" iyz="0.0" izz="0.3"/>
    </inertial>
    <!-- end for simulation -->
  </link>
  <joint name="panda_joint5" type="revolute">
    <safety_controller k_position="100.0" k_velocity="40.0" soft_lower_limit="-2.8973" soft_upper_limit="2.8973"/>
    <origin rpy="-1.57079632679 0 0" xyz="-0.0825 0.384 0"/>
    <parent link="panda_link4"/>
    <child link="panda_link5"/>
    <axis xyz="0 0 1"/>
    <limit effort="12" lower="-2.8973" upper="2.8973" velocity="2.6100"/>
    <!-- for simulation -->
    <dynamics damping="1.0"/>
    <!-- end for simulation -->
  </joint>
  <link name="panda_link6">
    <visual>
      <geometry>
        <mesh filename="package://franka_description/meshes/visual/link6.dae"/>
      </geometry>
    </visual>
    <collision>
      <geometry>
        <mesh filename="package://franka_description/meshes/collision/link6.stl"/>
      </geometry>
    </collision>
    <!-- for simulation -->
    <inertial>
      <origin rpy="0 0 0" xyz="0 0 0"/>
      <mass value="1.47"/>
      <inertia ixx="0.3" ixy="0.0" ixz="0.0" iyy="0.3" iyz="0.0" izz="0.3"/>
    </inertial>
    <!-- end for simulation -->
  </link>
  <joint name="panda_joint6" type="revolute">
    <safety_controller k_position="100.0" k_velocity="40.0" soft_lower_limit="-0.0175" soft_upper_limit="3.7525"/>
    <origin rpy="1.57079632679 0 0" xyz="0 0 0"/>
    <parent link="panda_link5"/>
    <child link="panda_link6"/>
    <axis xyz="0 0 1"/>
    <limit effort="12" lower="-0.0175" upper="3.7525" velocity="2.6100"/>
    <!-- for simulation -->
    <dynamics damping="1.0"/>
    <!-- end for simulation -->
  </joint>
  <link name="panda_link7">
    <visual>
      <geometry>
        <mesh filename="package://franka_description/meshes/visual/link7.dae"/>
      </geometry>
    </visual>
    <collision>
      <geometry>
        <mesh filename="package://franka_description/meshes/collision/link7.stl"/>
      </geometry>
    </collision>
    <!-- for simulation -->
    <inertial>
      <origin rpy="0 0 0" xyz="0 0 0"/>
      <mass value="0.45"/>
      <inertia ixx="0.3" ixy="0.0" ixz="0.0" iyy="0.3" iyz="0.0" izz="0.3"/>
    </inertial>
    <!-- end for simulation -->
  </link>
  <joint name="panda_joint7" type="revolute">
    <safety_controller k_position="100.0" k_velocity="40.0" soft_lower_limit="-2.8973" soft_upper_limit="2.8973"/>
    <origin rpy="1.57079632679 0 0" xyz="0.088 0 0"/>
    <parent link="panda_link6"/>
    <child link="panda_link7"/>
    <axis xyz="0 0 1"/>
    <limit effort="12" lower="-2.8973" upper="2.8973" velocity="2.6100"/>
    <!-- for simulation -->
    <dynamics damping="1.0"/>
    <!-- end for simulation -->
  </joint>
  <link name="panda_link8">
    <!-- for simulation -->
    <inertial>
      <origin rpy="0 0 0" xyz="0 0 0"/>
      <mass value="0.0"/>
      <inertia ixx="0.3" ixy="0.0" ixz="0.0" iyy="0.3" iyz="0.0" izz="0.3"/>
    </inertial>
    <!-- end for simulation -->
  </link>
  <joint name="panda_joint8" type="fixed">
    <origin rpy="0 0 0" xyz="0 0 0.107"/>
    <parent link="panda_link7"/>
    <child link="panda_link8"/>
    <axis xyz="0 0 0"/>
  </joint>
  <joint name="panda_hand_joint" type="fixed">
    <parent link="panda_link8"/>
    <child link="panda_hand"/>
    <origin rpy="0 0 -0.785398163397" xyz="0 0 0"/>
  </joint>
  <link name="panda_hand">
    <visual>
      <geometry>
        <mesh filename="package://franka_description/meshes/visual/hand.dae"/>
      </geometry>
    </visual>
    <collision>
      <geometry>
        <mesh filename="package://franka_description/meshes/collision/hand.stl"/>
      </geometry>
    </collision>
    <!-- for simulation -->
    <inertial>
      <origin rpy="0 0 0" xyz="0 0 0"/>
      <mass value="0.68"/>
      <inertia ixx="0.1" ixy="0.0" ixz="0.0" iyy="0.1" iyz="0.0" izz="0.1"/>
    </inertial>
    <!-- end for simulation -->
  </link>
  <link name="panda_leftfinger">
    <visual>
      <geometry>
        <mesh filename="package://franka_description/meshes/visual/finger.dae"/>
      </geometry>
    </visual>
    <collision>
      <geometry>
        <mesh filename="package://franka_description/meshes/collision/finger.stl"/>
      </geometry>
    </collision>
    <!-- for simulation -->
    <inertial>
      <origin rpy="0 0 0" xyz="0 0 0"/>
      <mass value="0.01"/>
      <inertia ixx="0.1" ixy="0.0" ixz="0.0" iyy="0.1" iyz="0.0" izz="0.1"/>
    </inertial>
    <!-- end for simulation -->
  </link>
  <link name="panda_rightfinger">
    <visual>
      <origin rpy="0 0 3.14159265359" xyz="0 0 0"/>
      <geometry>
        <mesh filename="package://franka_description/meshes/visual/finger.dae"/>
      </geometry>
    </visual>
    <collision>
      <origin rpy="0 0 3.14159265359" xyz="0 0 0"/>
      <geometry>
        <mesh filename="package://franka_description/meshes/collision/finger.stl"/>
      </geometry>
    </collision>
    <!-- for simulation -->
    <inertial>
      <origin rpy="0 0 0" xyz="0 0 0"/>
      <mass value="0.01"/>
      <inertia ixx="0.1" ixy="0.0" ixz="0.0" iyy="0.1" iyz="0.0" izz="0.1"/>
    </inertial>
    <!-- end for simulation -->
  </link>
  <joint name="panda_finger_joint1" type="prismatic">
    <parent link="panda_hand"/>
    <child link="panda_leftfinger"/>
    <origin rpy="0 0 0" xyz="0 0 0.0584"/>
    <axis xyz="0 1 0"/>
    <limit effort="20" lower="0.0" upper="0.04" velocity="0.2"/>
  </joint>
  <joint name="panda_finger_joint2" type="prismatic">
    <parent link="panda_hand"/>
    <child link="panda_rightfinger"/>
    <origin rpy="0 0 0" xyz="0 0 0.0584"/>
    <axis xyz="0 -1 0"/>
    <limit effort="20" lower="0.0" upper="0.04" velocity="0.2"/>
  </joint>
  <!-- Wrist mounted camera -->
  <joint name="panda_camera_joint" type="fixed">
    <parent link="panda_hand"/>
    <child link="panda_camera"/>
    <origin rpy="0 0 0" xyz="0.05 0 0.05"/>
    <axis xyz="0 1 0"/>
  </joint>
  <link name="panda_camera">
    <visual>
      <geometry>
        <box size="0.05 0.05 0.05"/>
      </geometry>
    </visual>
    <collision>
      <geometry>
        <box size="0.05 0.05 0.05"/>
      </geometry>
    </collision>
    <inertial>
      <origin rpy="0 0 0" xyz="0 0 0"/>
      <mass value="0.15625"/>
      <inertia ixx="0.000065104" ixy="0.0" ixz="0.0" iyy="0.000065104" iyz="0.0" izz="0.000065104"/>
    </inertial>
  </link>
  <joint name="panda_probe_cyl_joint" type="revolute">
    <parent link="panda_hand"/>
    <child link="panda_probe_cyl"/>
    <origin rpy="0 0 0" xyz="0 0 0.12"/>
    <axis xyz="0 1 0"/>
    <limit effort="20" lower="0.0" upper="0.0" velocity="0.0"/>
  </joint>
  <!-- 
    Masses and inertia based on density of PLA (1250 kg/m^3)
    Assumed uniform density 
    R = 0.03 m of ball
    r = 0.01 m of cyl
    L = 0.1 m of cyl
    I_ball = 2./5.*m_ball*R**2
    I_axis = 1./2.*m_cyl*r**2
    I_oAxis = 1./4.*m_cyl*r**2+1./12.*m_cyl*L**2
    -->
  <link name="panda_probe_cyl">
    <visual>
      <geometry>
        <cylinder length="0.1" radius="0.01"/>
      </geometry>
    </visual>
    <collision>
      <geometry>
        <cylinder length="0.1" radius="0.01"/>
      </geometry>
    </collision>
    <inertial>
      <origin rpy="0 0 0" xyz="0 0 0"/>
      <mass value="0.03926990816987242"/>
      <inertia ixx="3.3706671179140497e-05" ixy="0.0" ixz="0.0" iyy="3.3706671179140497e-05" iyz="0.0" izz="1.963495408493621e-06"/>
    </inertial>
  </link>
  <joint name="panda_probe_ball_joint" type="fixed">
    <parent link="panda_probe_cyl"/>
    <child link="panda_probe_ball"/>
    <origin rpy="0 0 0" xyz="0 0 0.07"/>
    <axis xyz="0 1 0"/>
  </joint>
  <link name="panda_probe_ball">
    <visual>
      <geometry>
        <sphere radius="0.03"/>
      </geometry>
    </visual>
    <collision>
      <geometry>
        <sphere radius="0.03"/>
      </geometry>
    </collision>
    <inertial>
      <origin rpy="0 0 0" xyz="0 0 0"/>
      <mass value="0.033749999999999995"/>
      <inertia ixx="1.2149999999999997e-05" ixy="0.0" ixz="0.0" iyy="1.2149999999999997e-05" iyz="0.0" izz="1.2149999999999997e-05"/>
    </inertial>
  </link>
  <gazebo reference="panda_link1">
    <sensor name="panda_link1_bumper" type="contact">
      <topic>/bump_topic/panda_link1</topic>
      <plugin filename="libgazebo_ros_bumper.so" name="gazebo_ros_bumper_controller_panda_link1">
        <topic>/bump_topic/panda_link1</topic>
        <alwaysOn>1</alwaysOn>
        <updateRate>100.0</updateRate>
        <bumperTopicName>/panda/bumper/panda_link1</bumperTopicName>
      </plugin>
      <contact>
        <collision>panda_link1_collision</collision>
        <topic>/bump_topic/panda_link1</topic>
      </contact>
      <alwaysOn>true</alwaysOn>
      <updateRate>10.0</updateRate>
    </sensor>
  </gazebo>
  <gazebo reference="panda_link2">
    <sensor name="panda_link2_bumper" type="contact">
      <topic>/bump_topic/panda_link2</topic>
      <plugin filename="libgazebo_ros_bumper.so" name="gazebo_ros_bumper_controller_panda_link2">
        <topic>/bump_topic/panda_link2</topic>
        <alwaysOn>1</alwaysOn>
        <updateRate>100.0</updateRate>
        <bumperTopicName>/panda/bumper/panda_link2</bumperTopicName>
      </plugin>
      <contact>
        <collision>panda_link2_collision</collision>
        <topic>/bump_topic/panda_link2</topic>
      </contact>
      <alwaysOn>true</alwaysOn>
      <updateRate>10.0</updateRate>
    </sensor>
  </gazebo>
  <gazebo reference="panda_link3">
    <sensor name="panda_link3_bumper" type="contact">
      <topic>/bump_topic/panda_link3</topic>
      <plugin filename="libgazebo_ros_bumper.so" name="gazebo_ros_bumper_controller_panda_link3">
        <topic>/bump_topic/panda_link3</topic>
        <alwaysOn>1</alwaysOn>
        <updateRate>100.0</updateRate>
        <bumperTopicName>/panda/bumper/panda_link3</bumperTopicName>
      </plugin>
      <contact>
        <collision>panda_link3_collision</collision>
        <topic>/bump_topic/panda_link3</topic>
      </contact>
      <alwaysOn>true</alwaysOn>
      <updateRate>10.0</updateRate>
    </sensor>
  </gazebo>
  <gazebo reference="panda_link4">
    <sensor name="panda_link4_bumper" type="contact">
      <topic>/bump_topic/panda_link4</topic>
      <plugin filename="libgazebo_ros_bumper.so" name="gazebo_ros_bumper_controller_panda_link4">
        <topic>/bump_topic/panda_link4</topic>
        <alwaysOn>1</alwaysOn>
        <updateRate>100.0</updateRate>
        <bumperTopicName>/panda/bumper/panda_link4</bumperTopicName>
      </plugin>
      <contact>
        <collision>panda_link4_collision</collision>
        <topic>/bump_topic/panda_link4</topic>
      </contact>
      <alwaysOn>true</alwaysOn>
      <updateRate>10.0</updateRate>
    </sensor>
  </gazebo>
  <gazebo reference="panda_link5">
    <sensor name="panda_link5_bumper" type="contact">
      <topic>/bump_topic/panda_link5</topic>
      <plugin filename="libgazebo_ros_bumper.so" name="gazebo_ros_bumper_controller_panda_link5">
        <topic>/bump_topic/panda_link5</topic>
        <alwaysOn>1</alwaysOn>
        <updateRate>100.0</updateRate>
        <bumperTopicName>/panda/bumper/panda_link5</bumperTopicName>
      </plugin>
      <contact>
        <collision>panda_link5_collision</collision>
        <topic>/bump_topic/panda_link5</topic>
      </contact>
      <alwaysOn>true</alwaysOn>
      <updateRate>10.0</updateRate>
    </sensor>
  </gazebo>
  <gazebo reference="panda_link6">
    <sensor name="panda_link6_bumper" type="contact">
      <topic>/bump_topic/panda_link6</topic>
      <plugin filename="libgazebo_ros_bumper.so" name="gazebo_ros_bumper_controller_panda_link6">
        <topic>/bump_topic/panda_link6</topic>
        <alwaysOn>1</alwaysOn>
        <updateRate>100.0</updateRate>
        <bumperTopicName>/panda/bumper/panda_link6</bumperTopicName>
      </plugin>
      <contact>
        <collision>panda_link6_collision</collision>
        <topic>/bump_topic/panda_link6</topic>
      </contact>
      <alwaysOn>true</alwaysOn>
      <updateRate>10.0</updateRate>
    </sensor>
  </gazebo>
  <gazebo reference="panda_link7">
    <sensor name="panda_link7_bumper" type="contact">
      <topic>/bump_topic/panda_link7</topic>
      <plugin filename="libgazebo_ros_bumper.so" name="gazebo_ros_bumper_controller_panda_link7">
        <topic>/bump_topic/panda_link7</topic>
        <alwaysOn>1</alwaysOn>
        <updateRate>100.0</updateRate>
        <bumperTopicName>/panda/bumper/panda_link7</bumperTopicName>
      </plugin>
      <contact>
        <collision>panda_link7_collision</collision>
        <collision>panda_link7_fixed_joint_lump__panda_hand_collision_1</collision>
        <topic>/bump_topic/panda_link7</topic>
      </contact>
      <alwaysOn>true</alwaysOn>
      <updateRate>10.0</updateRate>
    </sensor>
  </gazebo>
  <gazebo reference="panda_link8">
    <sensor name="panda_link8_bumper" type="contact">
      <topic>/bump_topic/panda_link8</topic>
      <plugin filename="libgazebo_ros_bumper.so" name="gazebo_ros_bumper_controller_panda_link8">
        <topic>/bump_topic/panda_link8</topic>
        <alwaysOn>1</alwaysOn>
        <updateRate>100.0</updateRate>
        <bumperTopicName>/panda/bumper/panda_link8</bumperTopicName>
      </plugin>
      <contact>
        <collision>panda_link8_collision</collision>
        <topic>/bump_topic/panda_link8</topic>
      </contact>
      <alwaysOn>true</alwaysOn>
      <updateRate>10.0</updateRate>
    </sensor>
  </gazebo>
  <gazebo reference="panda_hand">
    <sensor name="panda_hand_bumper" type="contact">
      <topic>/bump_topic/panda_hand</topic>
      <plugin filename="libgazebo_ros_bumper.so" name="gazebo_ros_bumper_controller_panda_hand">
        <topic>/bump_topic/panda_hand</topic>
        <alwaysOn>1</alwaysOn>
        <updateRate>100.0</updateRate>
        <bumperTopicName>/panda/bumper/panda_hand</bumperTopicName>
      </plugin>
      <contact>
        <collision>panda_hand_collision</collision>
        <topic>/bump_topic/panda_hand</topic>
      </contact>
      <alwaysOn>true</alwaysOn>
      <updateRate>10.0</updateRate>
    </sensor>
  </gazebo>
  <gazebo reference="panda_rightfinger">
    <sensor name="panda_rightfinger_bumper" type="contact">
      <topic>/bump_topic/panda_rightfinger</topic>
      <plugin filename="libgazebo_ros_bumper.so" name="gazebo_ros_bumper_controller_panda_rightfinger">
        <topic>/bump_topic/panda_rightfinger</topic>
        <alwaysOn>1</alwaysOn>
        <updateRate>100.0</updateRate>
        <bumperTopicName>/panda/bumper/panda_rightfinger</bumperTopicName>
      </plugin>
      <contact>
        <collision>panda_rightfinger_collision</collision>
        <topic>/bump_topic/panda_rightfinger</topic>
      </contact>
      <alwaysOn>true</alwaysOn>
      <updateRate>10.0</updateRate>
    </sensor>
  </gazebo>
  <gazebo reference="panda_leftfinger">
    <sensor name="panda_leftfinger_bumper" type="contact">
      <topic>/bump_topic/panda_leftfinger</topic>
      <plugin filename="libgazebo_ros_bumper.so" name="gazebo_ros_bumper_controller_panda_leftfinger">
        <topic>/bump_topic/panda_leftfinger</topic>
        <alwaysOn>1</alwaysOn>
        <updateRate>100.0</updateRate>
        <bumperTopicName>/panda/bumper/panda_leftfinger</bumperTopicName>
      </plugin>
      <contact>
        <collision>panda_leftfinger_collision</collision>
        <topic>/bump_topic/panda_leftfinger</topic>
      </contact>
      <alwaysOn>true</alwaysOn>
      <updateRate>10.0</updateRate>
    </sensor>
  </gazebo>
  <gazebo reference="panda_probe_cyl">
    <sensor name="panda_probe_cyl_bumper" type="contact">
      <topic>/bump_topic/panda_probe_cyl</topic>
      <plugin filename="libgazebo_ros_bumper.so" name="gazebo_ros_bumper_controller_panda_probe_cyl">
        <topic>/bump_topic/panda_probe_cyl</topic>
        <alwaysOn>1</alwaysOn>
        <updateRate>100.0</updateRate>
        <bumperTopicName>/panda/bumper/panda_probe_cyl</bumperTopicName>
      </plugin>
      <contact>
        <collision>panda_probe_cyl_collision</collision>
        <collision>panda_probe_cyl_collision</collision>
        <topic>/bump_topic/panda_probe_cyl</topic>
      </contact>
      <alwaysOn>true</alwaysOn>
      <updateRate>10.0</updateRate>
    </sensor>
  </gazebo>
  <gazebo reference="panda_probe_ball">
    <sensor name="panda_probe_ball_bumper" type="contact">
      <topic>/bump_topic/panda_probe_ball</topic>
      <plugin filename="libgazebo_ros_bumper.so" name="gazebo_ros_bumper_controller_panda_probe_ball">
        <topic>/bump_topic/panda_probe_ball</topic>
        <alwaysOn>1</alwaysOn>
        <updateRate>100.0</updateRate>
        <bumperTopicName>/panda/bumper/panda_probe_ball</bumperTopicName>
      </plugin>
      <contact>
        <collision>panda_probe_ball_collision</collision>
        <collision>panda_probe_cyl_fixed_joint_lump__panda_probe_ball_collision_1</collision>
        <topic>/bump_topic/panda_probe_ball</topic>
      </contact>
      <alwaysOn>true</alwaysOn>
      <updateRate>10.0</updateRate>
    </sensor>
  </gazebo>
  <!-- FT sensing at probe -->
  <gazebo reference="panda_probe_cyl_joint">
    <provideFeedback>true</provideFeedback>
  </gazebo>
  <gazebo>
    <plugin filename="libgazebo_ros_ft_sensor.so" name="ft_sensor_tool">
      <updateRate>1000.0</updateRate>
      <topicName>panda/ft/tool</topicName>
      <jointName>panda_probe_cyl_joint</jointName>
    </plugin>
  </gazebo>
  <!-- Link0 -->
  <gazebo reference="panda_link0">
    <material>Gazebo/Grey</material>
    <mu1>0.2</mu1>
    <mu2>0.2</mu2>
  </gazebo>
  <!-- Link1 -->
  <gazebo reference="panda_link1">
    <material>Gazebo/White</material>
    <mu1>0.2</mu1>
    <mu2>0.2</mu2>
  </gazebo>
  <!-- Link2 -->
  <gazebo reference="panda_link2">
    <material>Gazebo/White</material>
    <mu1>0.2</mu1>
    <mu2>0.2</mu2>
  </gazebo>
  <!-- Link3 -->
  <gazebo reference="panda_link3">
    <material>Gazebo/White</material>
    <mu1>0.2</mu1>
    <mu2>0.2</mu2>
  </gazebo>
  <!-- Link4 -->
  <gazebo reference="panda_link4">
    <material>Gazebo/White</material>
    <mu1>0.2</mu1>
    <mu2>0.2</mu2>
  </gazebo>
  <!-- Link5 -->
  <gazebo reference="panda_link5">
    <material>Gazebo/White</material>
    <mu1>0.2</mu1>
    <mu2>0.2</mu2>
  </gazebo>
  <!-- Link6 -->
  <gazebo reference="panda_link6">
    <material>Gazebo/White</material>
    <mu1>0.2</mu1>
    <mu2>0.2</mu2>
  </gazebo>
  <!-- Link7 -->
  <gazebo reference="panda_link7">
    <material>Gazebo/Grey</material>
    <mu1>0.2</mu1>
    <mu2>0.2</mu2>
  </gazebo>
  <!-- Link8 -->
  <gazebo reference="panda_link8">
    <material>Gazebo/Grey</material>
    <mu1>0.2</mu1>
    <mu2>0.2</mu2>
  </gazebo>
  <!-- LinkHand -->
  <gazebo reference="panda_hand">
    <material>Gazebo/Grey</material>
    <mu1>0.2</mu1>
    <mu2>0.2</mu2>
  </gazebo>
  <!-- LinkRightFinger -->
  <gazebo reference="panda_rightfinger">
    <material>Gazebo/Grey</material>
    <mu1>0.2</mu1>
    <mu2>0.2</mu2>
  </gazebo>
  <!-- LinkLeftFinger -->
  <gazebo reference="panda_leftfinger">
    <material>Gazebo/Grey</material>
    <mu1>0.2</mu1>
    <mu2>0.2</mu2>
  </gazebo>
  <!-- Load Gazebo lib and set the robot namespace -->
  <gazebo>
    <plugin filename="libgazebo_ros_control.so" name="gazebo_ros_control">
      <!-- <robotNamespace>/${robot_name}</robotNamespace> -->
    </plugin>
  </gazebo>
  <transmission name="panda_tran_1">
    <type>transmission_interface/SimpleTransmission</type>
    <joint name="panda_joint1">
      <hardwareInterface>hardware_interface/EffortJointInterface</hardwareInterface>
    </joint>
    <actuator name="panda_motor_1">
      <hardwareInterface>hardware_interface/EffortJointInterface</hardwareInterface>
      <mechanicalReduction>1</mechanicalReduction>
    </actuator>
  </transmission>
  <transmission name="panda_tran_2">
    <type>transmission_interface/SimpleTransmission</type>
    <joint name="panda_joint2">
      <hardwareInterface>hardware_interface/EffortJointInterface</hardwareInterface>
    </joint>
    <actuator name="panda_motor_2">
      <hardwareInterface>hardware_interface/EffortJointInterface</hardwareInterface>
      <mechanicalReduction>1</mechanicalReduction>
    </actuator>
  </transmission>
  <transmission name="panda_tran_3">
    <type>transmission_interface/SimpleTransmission</type>
    <joint name="panda_joint3">
      <hardwareInterface>hardware_interface/EffortJointInterface</hardwareInterface>
    </joint>
    <actuator name="panda_motor_3">
      <hardwareInterface>hardware_interface/EffortJointInterface</hardwareInterface>
      <mechanicalReduction>1</mechanicalReduction>
    </actuator>
  </transmission>
  <transmission name="panda_tran_4">
    <type>transmission_interface/SimpleTransmission</type>
    <joint name="panda_joint4">
      <hardwareInterface>hardware_interface/EffortJointInterface</hardwareInterface>
    </joint>
    <actuator name="panda_motor_4">
      <hardwareInterface>hardware_interface/EffortJointInterface</hardwareInterface>
      <mechanicalReduction>1</mechanicalReduction>
    </actuator>
  </transmission>
  <transmission name="panda_tran_5">
    <type>transmission_interface/SimpleTransmission</type>
    <joint name="panda_joint5">
      <hardwareInterface>hardware_interface/EffortJointInterface</hardwareInterface>
    </joint>
    <actuator name="panda_motor_5">
      <hardwareInterface>hardware_interface/EffortJointInterface</hardwareInterface>
      <mechanicalReduction>1</mechanicalReduction>
    </actuator>
  </transmission>
  <transmission name="panda_tran_6">
    <type>transmission_interface/SimpleTransmission</type>
    <joint name="panda_joint6">
      <hardwareInterface>hardware_interface/EffortJointInterface</hardwareInterface>
    </joint>
    <actuator name="panda_motor_6">
      <hardwareInterface>hardware_interface/EffortJointInterface</hardwareInterface>
      <mechanicalReduction>1</mechanicalReduction>
    </actuator>
  </transmission>
  <transmission name="panda_tran_7">
    <type>transmission_interface/SimpleTransmission</type>
    <joint name="panda_joint7">
      <hardwareInterface>hardware_interface/EffortJointInterface</hardwareInterface>
    </joint>
    <actuator name="panda_motor_7">
      <hardwareInterface>hardware_interface/EffortJointInterface</hardwareInterface>
      <mechanicalReduction>1</mechanicalReduction>
    </actuator>
  </transmission>
  <transmission name="panda_leftfinger">
    <type>transmission_interface/SimpleTransmission</type>
    <joint name="panda_finger_joint1">
      <hardwareInterface>hardware_interface/EffortJointInterface</hardwareInterface>
    </joint>
    <actuator name="panda_finger_joint1">
      <hardwareInterface>hardware_interface/EffortJointInterface</hardwareInterface>
      <mechanicalReduction>1</mechanicalReduction>
    </actuator>
  </transmission>
  <transmission name="panda_rightfinger">
    <type>transmission_interface/SimpleTransmission</type>
    <joint name="panda_finger_joint2">
      <hardwareInterface>hardware_interface/EffortJointInterface</hardwareInterface>
    </joint>
    <actuator name="panda_finger_joint2">
      <hardwareInterface>hardware_interface/EffortJointInterface</hardwareInterface>
      <mechanicalReduction>1</mechanicalReduction>
    </actuator>
  </transmission>
  <transmission name="panda_probe">
    <type>transmission_interface/SimpleTransmission</type>
    <joint name="panda_probe_cyl_joint">
      <hardwareInterface>hardware_interface/EffortJointInterface</hardwareInterface>
    </joint>
    <actuator name="panda_probe_cyl_joint">
      <hardwareInterface>hardware_interface/EffortJointInterface</hardwareInterface>
      <mechanicalReduction>1</mechanicalReduction>
    </actuator>
  </transmission>
  <!-- end for simulation -->
</robot>

